<?xml version="1.0"?>
<robot name="bipedal">
  
  <link name="waist">
    <visual>
      <geometry>
        <box size="0.16 0.60 .07"/>
      </geometry>
      <material name="red">
        <color rgba="1 0 0 1"/>
      </material>
    </visual>
    <collision>
      <geometry>
        <box size="0.16 0.60 .07"/>
      </geometry>
    </collision>
    <inertial>
      <mass value="3.2"/>
      <inertia ixx="1.0" ixy="0.0" ixz="0.0" iyy="1.0" iyz="0.0" izz="1.0"/>
    </inertial>
  </link>



  <link name="left_thigh">
    <visual>
      <geometry>
        <box size="0.16 0.15 0.50"/>
      </geometry>
      <material name="blue">
        <color rgba="0 0 1 1"/>
      </material>
    </visual>
    <collision>
      <geometry>
        <box size="0.16 0.15 0.50"/>
      </geometry>
    </collision>
    <inertial>
      <mass value="3.2"/>
      <inertia ixx="1.0" ixy="0.0" ixz="0.0" iyy="1.0" iyz="0.0" izz="1.0"/>
    </inertial>
  </link>


  <joint name="left_groin" type="continuous">
    <axis xyz="0 1 0"/>
    <parent link="waist"/>
    <child link="left_thigh"/>
    <origin rpy="0 0 0" xyz="0 -0.22 -0.35"/>
    <limit effort="100" velocity="100"/>
    <joint_properties damping="0.0" friction="0.0"/>
  </joint>



  <link name="right_thigh">
    <visual>
      <geometry>
        <box size="0.16 0.15 0.50"/>
      </geometry>
      <material name="blue">
        <color rgba="0 0 1 1"/>
      </material>
    </visual>
    <collision>
      <geometry>
        <box size="0.16 0.15 0.50"/>
      </geometry>
    </collision>
    <inertial>
      <mass value="3.2"/>
      <inertia ixx="1.0" ixy="0.0" ixz="0.0" iyy="1.0" iyz="0.0" izz="1.0"/>
    </inertial>
  </link>


  <joint name="right_groin" type="continuous">
    <axis xyz="0 1 0"/>
    <parent link="waist"/>
    <child link="right_thigh"/>
    <origin rpy="0 0 0" xyz="0 0.22 -0.35"/>
    <limit effort="100" velocity="100"/>
    <joint_properties damping="0.0" friction="0.0"/>
  </joint>



  <link name="left_leg">
    <visual>
      <geometry>
        <box size="0.16 0.15 0.50"/>
      </geometry>
      <material name="yellow">
        <color rgba="1 1 0 1"/>
      </material>
    </visual>
    <collision>
      <geometry>
        <box size="0.16 0.15 0.50"/>
      </geometry>
    </collision>
    <inertial>
      <mass value="3.2"/>
      <inertia ixx="1.0" ixy="0.0" ixz="0.0" iyy="1.0" iyz="0.0" izz="1.0"/>
    </inertial>
  </link>


  <joint name="left_knee" type="continuous">
    <axis xyz="0 1 0"/>
    <parent link="left_thigh"/>
    <child link="left_leg"/>
    <origin rpy="0 0 0" xyz="0 0 -0.565"/>
    <limit effort="100" velocity="100"/>
    <joint_properties damping="0.0" friction="0.0"/>
  </joint>



  <link name="right_leg">
    <visual>
      <geometry>
        <box size="0.16 0.15 0.50"/>
      </geometry>
      <material name="yellow">
        <color rgba="1 1 0 1"/>
      </material>
    </visual>
    <collision>
      <geometry>
        <box size="0.16 0.15 0.50"/>
      </geometry>
    </collision>
    <inertial>
      <mass value="3.2"/>
      <inertia ixx="1.0" ixy="0.0" ixz="0.0" iyy="1.0" iyz="0.0" izz="1.0"/>
    </inertial>
  </link>


  <joint name="right_knee" type="continuous">
    <axis xyz="0 1 0"/>
    <parent link="right_thigh"/>
    <child link="right_leg"/>
    <origin rpy="0 0 0" xyz="0 0 -0.565"/>
    <limit effort="100" velocity="100"/>
    <joint_properties damping="0.0" friction="0.0"/>
  </joint>


  <link name="left_foot">
    <visual>
      <geometry>
        <box size="0.4 0.20 0.05"/>
      </geometry>
      <material name="red">
        <color rgba="1 0 0 1"/>
      </material>
    </visual>
    <collision>
      <geometry>
        <box size="0.4 0.20 0.05"/>
      </geometry>
    </collision>
    <inertial>
      <mass value="3.2"/>
      <inertia ixx="1.0" ixy="0.0" ixz="0.0" iyy="1.0" iyz="0.0" izz="1.0"/>
    </inertial>
  </link>


  <joint name="left_ankle" type="continuous">
    <axis xyz="0 1 0"/>
    <parent link="left_leg"/>
    <child link="left_foot"/>
    <origin rpy="0 0 0" xyz="0.05 0 -0.34"/>
    <limit effort="100" velocity="100"/>
    <joint_properties damping="0.0" friction="0.0"/>
  </joint>


  <link name="right_foot">
    <visual>
      <geometry>
        <box size="0.4 0.20 0.05"/>
      </geometry>
      <material name="red">
        <color rgba="1 0 0 1"/>
      </material>
    </visual>
    <collision>
      <geometry>
        <box size="0.4 0.20 0.05"/>
      </geometry>
    </collision>
    <inertial>
      <mass value="3.2"/>
      <inertia ixx="1.0" ixy="0.0" ixz="0.0" iyy="1.0" iyz="0.0" izz="1.0"/>
    </inertial>
  </link>


  <joint name="right_ankle" type="continuous">
    <axis xyz="0 1 0"/>
    <parent link="right_leg"/>
    <child link="right_foot"/>
    <origin rpy="0 0 0" xyz="0.05 0 -0.34"/>
    <limit effort="100" velocity="100"/>
    <joint_properties damping="0.0" friction="0.0"/>
  </joint>






</robot>
