<?xml version="1.0"?>
<robot name="spider">

  <link name="base_chassis_link">
    <visual>
      <geometry>
        <box size="0.40 0.40 0.10"/>
      </geometry>
      <material name="red">
        <color rgba="1 0 0 1"/>
      </material>
    </visual>
    <collision>
      <geometry>
       <box size="0.40 0.40 0.10"/>
      </geometry>
    </collision>
    <inertial>
      <mass value="0.2"/>
      <inertia ixx="1.0" ixy="0.0" ixz="0.0" iyy="1.0" iyz="0.0" izz="1.0"/>
    </inertial>
  </link>

  
  
  
  
  
  <link name="front_right_1">
    <visual>
      <geometry>
        <box size="0.032 0.032 0.032"/>
      </geometry>
      <material name="green">
        <color rgba="0 1 0 1"/>
      </material>
    </visual>
    <collision>
      <geometry>
       <box size="0.032 0.032 0.032"/>
      </geometry>
    </collision>
    <inertial>
      <mass value="0.06"/>
      <inertia ixx="1.0" ixy="0.0" ixz="0.0" iyy="1.0" iyz="0.0" izz="1.0"/>
    </inertial>
  </link>
  
  <joint name="front_right_1_joint" type="continuous">
    <axis xyz="0 0 1"/>
    <parent link="base_chassis_link"/>
    <child link="front_right_1"/>
    <origin rpy="0 0 0" xyz="0.184 -0.216 0"/>
    <limit effort="100" velocity="100"/>
    <joint_properties damping="0.0" friction="0.0"/>
  </joint>
 
 
  <link name="front_right_2">
    <visual>
      <geometry>
        <box size="0.032 0.032 0.032"/>
      </geometry>
      <material name="blue">
        <color rgba="0 0 1 1"/>
      </material>
    </visual>
    <collision>
      <geometry>
       <box size="0.032 0.032 0.032"/>
      </geometry>
    </collision>
    <inertial>
      <mass value="0.06"/>
      <inertia ixx="1.0" ixy="0.0" ixz="0.0" iyy="1.0" iyz="0.0" izz="1.0"/>
    </inertial>
  </link>
  
  <joint name="front_right_2_joint" type="continuous">
    <axis xyz="1 0 0"/>
    <parent link="front_right_1"/>
    <child link="front_right_2"/>
    <origin rpy="0 0 0" xyz="0 -0.032 0"/>
    <limit effort="100" velocity="100"/>
    <joint_properties damping="0.0" friction="0.0"/>
  </joint>
  

  <link name="front_right_3">
    <visual>
      <geometry>
        <box size="0.032 0.2 0.032"/>
      </geometry>
      <material name="yellow">
        <color rgba="1 1 0 1"/>
      </material>
    </visual>
    <collision>
      <geometry>
       <box size="0.032 0.2 0.032"/>
      </geometry>
    </collision>
    <inertial>
      <mass value="0.015"/>
      <inertia ixx="1.0" ixy="0.0" ixz="0.0" iyy="1.0" iyz="0.0" izz="1.0"/>
    </inertial>
  </link>
  
  <joint name="front_right_3_joint" type="fixed">
    <axis xyz="1 0 0"/>
    <parent link="front_right_2"/>
    <child link="front_right_3"/>
    <origin rpy="0 0 0" xyz="0 -0.116 0"/>
    <limit effort="100" velocity="100"/>
    <joint_properties damping="0.0" friction="0.0"/>
  </joint>
  
  
  <link name="front_right_4">
    <visual>
      <geometry>
        <box size="0.032 0.032 0.032"/>
      </geometry>
      <material name="blue">
        <color rgba="0 0 1 1"/>
      </material>
    </visual>
    <collision>
      <geometry>
       <box size="0.032 0.032 0.032"/>
      </geometry>
    </collision>
    <inertial>
      <mass value="0.06"/>
      <inertia ixx="1.0" ixy="0.0" ixz="0.0" iyy="1.0" iyz="0.0" izz="1.0"/>
    </inertial>
  </link>
  
  <joint name="front_right_4_joint" type="continuous">
    <axis xyz="1 0 0"/>
    <parent link="front_right_3"/>
    <child link="front_right_4"/>
    <origin rpy="0 0 0" xyz="0 -0.116 0"/>
    <limit effort="100" velocity="100"/>
    <joint_properties damping="0.0" friction="0.0"/>
  </joint>
  
  
  <link name="front_right_5">
    <visual>
      <geometry>
        <cylinder length="0.2" radius="0.016"/>
      </geometry>
      <material name="yellow">
        <color rgba="1 1 0 1"/>
      </material>
    </visual>
    <collision>
      <geometry>
       <cylinder length="0.2" radius="0.016"/>
      </geometry>
    </collision>
    <inertial>
      <mass value="0.015"/>
      <inertia ixx="1.0" ixy="0.0" ixz="0.0" iyy="1.0" iyz="0.0" izz="1.0"/>
    </inertial>
  </link>
  
  <joint name="front_right_5_joint" type="fixed">
    <axis xyz="1 0 0"/>
    <parent link="front_right_4"/>
    <child link="front_right_5"/>
    <origin rpy="1.5708 0 0" xyz="0 -0.116 0"/>
    <limit effort="100" velocity="100"/>
    <joint_properties damping="0.0" friction="0.0"/>
  </joint>
  
  
  
  
  
  
  <link name="front_left_1">
    <visual>
      <geometry>
        <box size="0.032 0.032 0.032"/>
      </geometry>
      <material name="green">
        <color rgba="0 1 0 1"/>
      </material>
    </visual>
    <collision>
      <geometry>
       <box size="0.032 0.032 0.032"/>
      </geometry>
    </collision>
    <inertial>
      <mass value="0.06"/>
      <inertia ixx="1.0" ixy="0.0" ixz="0.0" iyy="1.0" iyz="0.0" izz="1.0"/>
    </inertial>
  </link>
  
  <joint name="front_left_1_joint" type="continuous">
    <axis xyz="0 0 1"/>
    <parent link="base_chassis_link"/>
    <child link="front_left_1"/>
    <origin rpy="0 0 0" xyz="0.184 0.216 0"/>
    <limit effort="100" velocity="100"/>
    <joint_properties damping="0.0" friction="0.0"/>
  </joint>
 
 
  <link name="front_left_2">
    <visual>
      <geometry>
        <box size="0.032 0.032 0.032"/>
      </geometry>
      <material name="blue">
        <color rgba="0 0 1 1"/>
      </material>
    </visual>
    <collision>
      <geometry>
       <box size="0.032 0.032 0.032"/>
      </geometry>
    </collision>
    <inertial>
      <mass value="0.06"/>
      <inertia ixx="1.0" ixy="0.0" ixz="0.0" iyy="1.0" iyz="0.0" izz="1.0"/>
    </inertial>
  </link>
  
  <joint name="front_left_2_joint" type="continuous">
    <axis xyz="1 0 0"/>
    <parent link="front_left_1"/>
    <child link="front_left_2"/>
    <origin rpy="0 0 0" xyz="0 0.032 0"/>
    <limit effort="100" velocity="100"/>
    <joint_properties damping="0.0" friction="0.0"/>
  </joint>
  

  <link name="front_left_3">
    <visual>
      <geometry>
        <box size="0.032 0.2 0.032"/>
      </geometry>
      <material name="yellow">
        <color rgba="1 1 0 1"/>
      </material>
    </visual>
    <collision>
      <geometry>
       <box size="0.032 0.2 0.032"/>
      </geometry>
    </collision>
    <inertial>
      <mass value="0.015"/>
      <inertia ixx="1.0" ixy="0.0" ixz="0.0" iyy="1.0" iyz="0.0" izz="1.0"/>
    </inertial>
  </link>
  
  <joint name="front_left_3_joint" type="fixed">
    <axis xyz="1 0 0"/>
    <parent link="front_left_2"/>
    <child link="front_left_3"/>
    <origin rpy="0 0 0" xyz="0 0.116 0"/>
    <limit effort="100" velocity="100"/>
    <joint_properties damping="0.0" friction="0.0"/>
  </joint>
  
  
  <link name="front_left_4">
    <visual>
      <geometry>
        <box size="0.032 0.032 0.032"/>
      </geometry>
      <material name="blue">
        <color rgba="0 0 1 1"/>
      </material>
    </visual>
    <collision>
      <geometry>
       <box size="0.032 0.032 0.032"/>
      </geometry>
    </collision>
    <inertial>
      <mass value="0.06"/>
      <inertia ixx="1.0" ixy="0.0" ixz="0.0" iyy="1.0" iyz="0.0" izz="1.0"/>
    </inertial>
  </link>
  
  <joint name="front_left_4_joint" type="continuous">
    <axis xyz="1 0 0"/>
    <parent link="front_left_3"/>
    <child link="front_left_4"/>
    <origin rpy="0 0 0" xyz="0 0.116 0"/>
    <limit effort="100" velocity="100"/>
    <joint_properties damping="0.0" friction="0.0"/>
  </joint>
  
  
  <link name="front_left_5">
    <visual>
      <geometry>
        <cylinder length="0.2" radius="0.016"/>
      </geometry>
      <material name="yellow">
        <color rgba="1 1 0 1"/>
      </material>
    </visual>
    <collision>
      <geometry>
       <cylinder length="0.2" radius="0.016"/>
      </geometry>
    </collision>
    <inertial>
      <mass value="0.015"/>
      <inertia ixx="1.0" ixy="0.0" ixz="0.0" iyy="1.0" iyz="0.0" izz="1.0"/>
    </inertial>
  </link>
  
  <joint name="front_left_5_joint" type="fixed">
    <axis xyz="1 0 0"/>
    <parent link="front_left_4"/>
    <child link="front_left_5"/>
    <origin rpy="1.5708 0 0" xyz="0 0.116 0"/>
    <limit effort="100" velocity="100"/>
    <joint_properties damping="0.0" friction="0.0"/>
  </joint>
  
  
  
  
  
  <link name="back_right_1">
    <visual>
      <geometry>
        <box size="0.032 0.032 0.032"/>
      </geometry>
      <material name="green">
        <color rgba="0 1 0 1"/>
      </material>
    </visual>
    <collision>
      <geometry>
       <box size="0.032 0.032 0.032"/>
      </geometry>
    </collision>
    <inertial>
      <mass value="0.06"/>
      <inertia ixx="1.0" ixy="0.0" ixz="0.0" iyy="1.0" iyz="0.0" izz="1.0"/>
    </inertial>
  </link>
  
  <joint name="back_right_1_joint" type="continuous">
    <axis xyz="0 0 1"/>
    <parent link="base_chassis_link"/>
    <child link="back_right_1"/>
    <origin rpy="0 0 0" xyz="-0.184 -0.216 0"/>
    <limit effort="100" velocity="100"/>
    <joint_properties damping="0.0" friction="0.0"/>
  </joint>
 
 
  <link name="back_right_2">
    <visual>
      <geometry>
        <box size="0.032 0.032 0.032"/>
      </geometry>
      <material name="blue">
        <color rgba="0 0 1 1"/>
      </material>
    </visual>
    <collision>
      <geometry>
       <box size="0.032 0.032 0.032"/>
      </geometry>
    </collision>
    <inertial>
      <mass value="0.06"/>
      <inertia ixx="1.0" ixy="0.0" ixz="0.0" iyy="1.0" iyz="0.0" izz="1.0"/>
    </inertial>
  </link>
  
  <joint name="back_right_2_joint" type="continuous">
    <axis xyz="1 0 0"/>
    <parent link="back_right_1"/>
    <child link="back_right_2"/>
    <origin rpy="0 0 0" xyz="0 -0.032 0"/>
    <limit effort="100" velocity="100"/>
    <joint_properties damping="0.0" friction="0.0"/>
  </joint>
  

  <link name="back_right_3">
    <visual>
      <geometry>
        <box size="0.032 0.2 0.032"/>
      </geometry>
      <material name="yellow">
        <color rgba="1 1 0 1"/>
      </material>
    </visual>
    <collision>
      <geometry>
       <box size="0.032 0.2 0.032"/>
      </geometry>
    </collision>
    <inertial>
      <mass value="0.015"/>
      <inertia ixx="1.0" ixy="0.0" ixz="0.0" iyy="1.0" iyz="0.0" izz="1.0"/>
    </inertial>
  </link>
  
  <joint name="back_right_3_joint" type="fixed">
    <axis xyz="1 0 0"/>
    <parent link="back_right_2"/>
    <child link="back_right_3"/>
    <origin rpy="0 0 0" xyz="0 -0.116 0"/>
    <limit effort="100" velocity="100"/>
    <joint_properties damping="0.0" friction="0.0"/>
  </joint>
  
  
  <link name="back_right_4">
    <visual>
      <geometry>
        <box size="0.032 0.032 0.032"/>
      </geometry>
      <material name="blue">
        <color rgba="0 0 1 1"/>
      </material>
    </visual>
    <collision>
      <geometry>
       <box size="0.032 0.032 0.032"/>
      </geometry>
    </collision>
    <inertial>
      <mass value="0.06"/>
      <inertia ixx="1.0" ixy="0.0" ixz="0.0" iyy="1.0" iyz="0.0" izz="1.0"/>
    </inertial>
  </link>
  
  <joint name="back_right_4_joint" type="continuous">
    <axis xyz="1 0 0"/>
    <parent link="back_right_3"/>
    <child link="back_right_4"/>
    <origin rpy="0 0 0" xyz="0 -0.116 0"/>
    <limit effort="100" velocity="100"/>
    <joint_properties damping="0.0" friction="0.0"/>
  </joint>
  
  
  <link name="back_right_5">
    <visual>
      <geometry>
        <cylinder length="0.2" radius="0.016"/>
      </geometry>
      <material name="yellow">
        <color rgba="1 1 0 1"/>
      </material>
    </visual>
    <collision>
      <geometry>
       <cylinder length="0.2" radius="0.016"/>
      </geometry>
    </collision>
    <inertial>
      <mass value="0.015"/>
      <inertia ixx="1.0" ixy="0.0" ixz="0.0" iyy="1.0" iyz="0.0" izz="1.0"/>
    </inertial>
  </link>
  
  <joint name="back_right_5_joint" type="fixed">
    <axis xyz="1 0 0"/>
    <parent link="back_right_4"/>
    <child link="back_right_5"/>
    <origin rpy="1.5708 0 0" xyz="0 -0.116 0"/>
    <limit effort="100" velocity="100"/>
    <joint_properties damping="0.0" friction="0.0"/>
  </joint>
  
  
  
  
  
  
  
  
  <link name="back_left_1">
    <visual>
      <geometry>
        <box size="0.032 0.032 0.032"/>
      </geometry>
      <material name="green">
        <color rgba="0 1 0 1"/>
      </material>
    </visual>
    <collision>
      <geometry>
       <box size="0.032 0.032 0.032"/>
      </geometry>
    </collision>
    <inertial>
      <mass value="0.06"/>
      <inertia ixx="1.0" ixy="0.0" ixz="0.0" iyy="1.0" iyz="0.0" izz="1.0"/>
    </inertial>
  </link>
  
  <joint name="back_left_1_joint" type="continuous">
    <axis xyz="0 0 1"/>
    <parent link="base_chassis_link"/>
    <child link="back_left_1"/>
    <origin rpy="0 0 0" xyz="-0.184 0.216 0"/>
    <limit effort="100" velocity="100"/>
    <joint_properties damping="0.0" friction="0.0"/>
  </joint>
 
 
  <link name="back_left_2">
    <visual>
      <geometry>
        <box size="0.032 0.032 0.032"/>
      </geometry>
      <material name="blue">
        <color rgba="0 0 1 1"/>
      </material>
    </visual>
    <collision>
      <geometry>
       <box size="0.032 0.032 0.032"/>
      </geometry>
    </collision>
    <inertial>
      <mass value="0.06"/>
      <inertia ixx="1.0" ixy="0.0" ixz="0.0" iyy="1.0" iyz="0.0" izz="1.0"/>
    </inertial>
  </link>
  
  <joint name="back_left_2_joint" type="continuous">
    <axis xyz="1 0 0"/>
    <parent link="back_left_1"/>
    <child link="back_left_2"/>
    <origin rpy="0 0 0" xyz="0 0.032 0"/>
    <limit effort="100" velocity="100"/>
    <joint_properties damping="0.0" friction="0.0"/>
  </joint>
  

  <link name="back_left_3">
    <visual>
      <geometry>
        <box size="0.032 0.2 0.032"/>
      </geometry>
      <material name="yellow">
        <color rgba="1 1 0 1"/>
      </material>
    </visual>
    <collision>
      <geometry>
       <box size="0.032 0.2 0.032"/>
      </geometry>
    </collision>
    <inertial>
      <mass value="0.015"/>
      <inertia ixx="1.0" ixy="0.0" ixz="0.0" iyy="1.0" iyz="0.0" izz="1.0"/>
    </inertial>
  </link>
  
  <joint name="back_left_3_joint" type="fixed">
    <axis xyz="1 0 0"/>
    <parent link="back_left_2"/>
    <child link="back_left_3"/>
    <origin rpy="0 0 0" xyz="0 0.116 0"/>
    <limit effort="100" velocity="100"/>
    <joint_properties damping="0.0" friction="0.0"/>
  </joint>
  
  
  <link name="back_left_4">
    <visual>
      <geometry>
        <box size="0.032 0.032 0.032"/>
      </geometry>
      <material name="blue">
        <color rgba="0 0 1 1"/>
      </material>
    </visual>
    <collision>
      <geometry>
       <box size="0.032 0.032 0.032"/>
      </geometry>
    </collision>
    <inertial>
      <mass value="0.06"/>
      <inertia ixx="1.0" ixy="0.0" ixz="0.0" iyy="1.0" iyz="0.0" izz="1.0"/>
    </inertial>
  </link>
  
  <joint name="back_left_4_joint" type="continuous">
    <axis xyz="1 0 0"/>
    <parent link="back_left_3"/>
    <child link="back_left_4"/>
    <origin rpy="0 0 0" xyz="0 0.116 0"/>
    <limit effort="100" velocity="100"/>
    <joint_properties damping="0.0" friction="0.0"/>
  </joint>
  
  
  <link name="back_left_5">
    <visual>
      <geometry>
        <cylinder length="0.2" radius="0.016"/>
      </geometry>
      <material name="yellow">
        <color rgba="1 1 0 1"/>
      </material>
    </visual>
    <collision>
      <geometry>
       <cylinder length="0.2" radius="0.016"/>
      </geometry>
    </collision>
    <inertial>
      <mass value="0.015"/>
      <inertia ixx="1.0" ixy="0.0" ixz="0.0" iyy="1.0" iyz="0.0" izz="1.0"/>
    </inertial>
  </link>
  
  <joint name="back_left_5_joint" type="fixed">
    <axis xyz="1 0 0"/>
    <parent link="back_left_4"/>
    <child link="back_left_5"/>
    <origin rpy="1.5708 0 0" xyz="0 0.116 0"/>
    <limit effort="100" velocity="100"/>
    <joint_properties damping="0.0" friction="0.0"/>
  </joint>
  
  
  

</robot>
