<?xml version="1.0" ?>
<robot name="plane">
  <link name="planeLink">
  <contact>
      <lateral_friction value="1"/>
  </contact>
    <inertial>
      <origin rpy="0 0 0" xyz="0 0 0"/>
       <mass value="0"/>
       <inertia ixx="0" ixy="0" ixz="0" iyy="0" iyz="0" izz="0"/>
    </inertial>
    <visual>
      <origin rpy="0 0 0" xyz="0 0 0"/>
      <geometry>
				<mesh filename="plane.obj" scale="1 1 1"/>
      </geometry>
       <material name="white">
        <color rgba="1 1 1 1"/>
      </material>
    </visual>
    <collision>
      <origin rpy="0 0 0" xyz="0 0 -5"/>
      <geometry>
	 	<box size="30 30 10"/>
      </geometry>
    </collision>
  </link>
  
  
  <link name="stand">
    <visual>
      <geometry>
        <box size="0.1 0.1 1"/>
      </geometry>
      <material name="blue">
        <color rgba="0 0 1 1"/>
      </material>
    </visual>
    <collision>
      <geometry>
        <box size="0.1 0.1 1"/>
      </geometry>
    </collision>
    <inertial>
      <mass value="5"/>
      <inertia ixx="1.0" ixy="0.0" ixz="0.0" iyy="1.0" iyz="0.0" izz="1.0"/>
    </inertial>
  </link>


  <joint name="base_joint" type="fixed">
    <axis xyz="0 0 1"/>
    <parent link="planeLink"/>
    <child link="stand"/>
    <origin rpy="0 0 0" xyz="0 0 0"/>
  </joint>


  <link name="y_axis_rotor">
    <visual>
      <geometry>
        <box size="0.1 0.1 0.1"/>
      </geometry>
      <material name="red">
        <color rgba="1 0 0 1"/>
      </material>
    </visual>
    <collision>
      <geometry>
        <box size="0.1 0.1 0.1"/>
      </geometry>
    </collision>
    <inertial>
      <mass value="5"/>
      <inertia ixx="1.0" ixy="0.0" ixz="0.0" iyy="1.0" iyz="0.0" izz="1.0"/>
    </inertial>
  </link>


  <joint name="y_rotor_joint" type="continuous">
    <axis xyz="0 1 0"/>
    <parent link="stand"/>
    <child link="y_axis_rotor"/>
    <origin rpy="0 0 0" xyz="0 0 0.58"/>
        
  </joint>


  <link name="x_axis_rotor">
    <visual>
      <geometry>
        <box size="0.1 0.1 0.1"/>
      </geometry>
      <material name="yellow">
        <color rgba="1 1 0 1"/>
      </material>
    </visual>
    <collision>
      <geometry>
        <box size="0.1 0.1 0.1"/>
      </geometry>
    </collision>
    <inertial>
      <mass value="5"/>
      <inertia ixx="1.0" ixy="0.0" ixz="0.0" iyy="1.0" iyz="0.0" izz="1.0"/>
    </inertial>
  </link>


  <joint name="x_rotor_joint" type="continuous">
    <axis xyz="1 0 0"/>
    <parent link="y_axis_rotor"/>
    <child link="x_axis_rotor"/>
    <origin rpy="0 0 0" xyz="0 0 0.13"/>
  </joint>


  <link name="table">
    <contact>
       <lateral_friction value="1"/>
    </contact>
    <visual>
      <geometry>
        <box size="2 2 0.1"/>
      </geometry>
      <material name="green">
        <color rgba="0 1 0 1"/>
      </material>
    </visual>
    <collision>
      <geometry>
        <box size="2 2 0.1"/>
      </geometry>
    </collision>
    <inertial>
      <mass value="5"/>
      <inertia ixx="1.0" ixy="0.0" ixz="0.0" iyy="1.0" iyz="0.0" izz="1.0"/>
    </inertial>
  </link>


  <joint name="table_joint" type="fixed">
    <axis xyz="1 0 0"/>
    <parent link="x_axis_rotor"/>
    <child link="table"/>
    <origin rpy="0 0 0" xyz="0 0 0.5"/>
  </joint>



  


</robot>

